Workbook

Sheet README
A1: CircularFibre Group (fictional) – LCA / PCF, CO₂ Accounting & Sustainable Procurement Toolkit
A2: Portfolio model: waste paper recycling → recycled cartonboard → folding cartons & gypsum board liners. All data illustrative.
A4: PURPOSE | B4: Integrated Excel toolkit covering the core tasks of a Sustainable Procurement / Carbon Accounting role: product carbon footprints (PCF/LCA), corporate GHG inventory (Scope 1-2-3), supplier CO₂ data collection & validation, ESG supplier scorecards, KPIs, decarbonisation levers, supplier survey and training plan.
A5: BUSINESS MODEL | B5: Circular value chain: (1) recovered paper (RCP) is collected and sorted, (2) pulped and converted into 100% recycled cartonboard in own board mills, (3) board is converted into folding cartons in own converting plants or sold externally, (4) part of the board is used as liner paper in own gypsum board plants. Converting trim waste (~12%) is returned to the mill as RCP (closed loop).
A6: STANDARDS APPLIED | B6: ISO 14040/14044 (LCA framework), ISO 14067 (PCF), GHG Protocol Corporate Standard + Scope 3 Standard, GHG Protocol Product Standard, WBCSD PACT Pathfinder Framework v3 (data quality ratings, PCF exchange), CEPI Carbon Footprint Framework for paper & board, EN 15804 (construction products – gypsum board EPD), EcoVadis methodology (4 themes).
A7: SYSTEM BOUNDARY | B7: PCFs: cradle-to-gate (A1-A3), fossil GHG in kg CO₂e, GWP100 (IPCC AR6). Recovered paper enters burden-free (cut-off / recycled-content approach) – only collection, sorting and transport are allocated. Biogenic carbon stored in the product is reported separately as a memo item (not netted). Folding carton additionally shows an optional cradle-to-customer value.
A8: SHEET MAP | B8: Company_Inputs → production volumes & activity data | Emission_Factors → EF library with sources | PCF_Board / PCF_FoldingCarton / PCF_GypsumBoard → product footprints | Supplier_Register → supplier volumes, supplier PCFs, PACT data quality, primary-vs-secondary logic | GHG_Inventory → Scope 1/2/3 by category | Supplier_Scorecard → weighted ESG scoring & risk prioritisation | Decarbonisation → levers, reduction potential, abatement cost | KPI_Dashboard → procurement & climate KPIs with charts | Supplier_Survey → questionnaire template | Training_Plan → internal awareness programme
A9: COLOUR LEGEND | B9: Blue text on yellow fill = input / assumption (edit these) · Black = formula (do not overwrite) · Green = link to another sheet · Grey rows = totals.
A10: HOW TO UPDATE | B10: 1) Update production volumes in Company_Inputs. 2) Replace illustrative factors in Emission_Factors with licensed data (ecoinvent, GaBi/Sphera, UBA, DESNZ, AIB residual mix). 3) Enter supplier volumes, supplier-specific PCFs and the 5 PACT data-quality indicators in Supplier_Register – the model automatically uses supplier data if DQR ≤ threshold, otherwise falls back to secondary data. 4) Enter ESG assessment results (EcoVadis, survey) in Supplier_Scorecard. 5) Review KPI_Dashboard and Decarbonisation.
A11: DATA QUALITY LOGIC | B11: PACT Data Quality Rating (DQR) = average of technological, geographical, temporal representativeness, completeness and reliability (1 = very good … 5 = very poor). Supplier PCFs with DQR above the acceptance threshold are flagged and replaced by secondary EFs until the supplier improves its data.
A12: LIMITATIONS | B12: Company, suppliers and all numbers are FICTIONAL and for demonstration only. Emission factors are rounded, indicative values typical of published sources – they are not verified and must be replaced before any external use (CSRD/ESRS E1, customer PCF requests, EcoVadis).

Sheet KPI_Dashboard
A1: KPI Dashboard – Sustainable Procurement & Carbon Accounting
A2: ="Reporting year "&Company_Inputs!$B$6&" · fictional data · all values formula-linked" -> Reporting year 2025 · fictional data · all values formula-linked
A4: # | B4: KPI | C4: Actual | D4: Unit | E4: Target | F4: Status | G4: Definition / purpose
A5: Climate
A6: 1 | B6: Total GHG emissions (S1 + S2 MB + S3) | C6: =GHG_Inventory!$G$55 -> 511098.45 | D6: t CO₂e | E6: – | F6: Monitor | G6: Corporate inventory, GHG Protocol
A7: 2 | B7: Scope 1 | C7: =GHG_Inventory!$G$51 -> 202028.52 | D7: t CO₂e | E7: – | F7: Monitor
A8: 3 | B8: Scope 2 (market-based) | C8: =GHG_Inventory!$G$53 -> 107900.08 | D8: t CO₂e | E8: – | F8: Monitor | G8: Location-based in GHG_Inventory
A9: 4 | B9: Scope 3 | C9: =GHG_Inventory!$G$54 -> 201169.85 | D9: t CO₂e | E9: – | F9: Monitor
A10: 5 | B10: Scope 3 share of total | C10: =GHG_Inventory!$G$56 -> 0.39360293 | D10: % | E10: – | F10: Monitor | G10: Shows relevance of supplier engagement
A11: Product Carbon Footprints
A12: 6 | B12: PCF recycled cartonboard | C12: =PCF_Board!$G$21 -> 716.7375 | D12: kg CO₂e/t | E12: 550 | F12: =IF(C12<=E12,"✔ On track","✖ Gap") -> ✖ Gap | G12: Cradle-to-gate, fossil
A13: 7 | B13: PCF folding carton | C13: =PCF_FoldingCarton!$G$21 -> 1056.5885 | D13: kg CO₂e/t | E13: 750 | F13: =IF(C13<=E13,"✔ On track","✖ Gap") -> ✖ Gap | G13: Cradle-to-gate
A14: 8 | B14: PCF gypsum board | C14: =PCF_GypsumBoard!$G$28 -> 2.262795 | D14: kg CO₂e/m² | E14: 1.8 | F14: =IF(C14<=E14,"✔ On track","✖ Gap") -> ✖ Gap | G14: A1-A3, EN 15804
A15: Supplier data & procurement
A16: 9 | B16: Cat 1 emissions based on supplier-specific data | C16: =SUMIFS(Supplier_Register!$S$6:$S$21,Supplier_Register!$R$6:$R$21,"Supplier-specific")/Supplier_Register!$S$22 -> 0.52482148 | D16: % | E16: 0.5 | F16: =IF(C16>=E16,"✔ On track","✖ Gap") -> ✔ On track | G16: Primary data share (SBTi / PACT)
A17: 10 | B17: Suppliers (by spend) with EcoVadis assessment | C17: =SUMIFS(Supplier_Scorecard!$P$7:$P$22,Supplier_Scorecard!$D$7:$D$22,">0")/SUM(Supplier_Scorecard!$P$7:$P$22) -> 0.63561077 | D17: % | E17: 0.8 | F17: =IF(C17>=E17,"✔ On track","✖ Gap") -> ✖ Gap | G17: Rating coverage
A18: 11 | B18: Spend with A/B-rated suppliers | C18: =(SUMIFS(Supplier_Scorecard!$P$7:$P$22,Supplier_Scorecard!$O$7:$O$22,"A*")+SUMIFS(Supplier_Scorecard!$P$7:$P$22,Supplier_Scorecard!$O$7:$O$22,"B*"))/SUM(Supplier_Scorecard!$P$7:$P$22) -> 0.45238095 | D18: % | E18: 0.75 | F18: =IF(C18>=E18,"✔ On track","✖ Gap") -> ✖ Gap | G18: Scorecard result
A19: 12 | B19: Cat 1 emissions with suppliers having SBTi targets | C19: =SUMIFS(Supplier_Scorecard!$Q$7:$Q$22,Supplier_Scorecard!$J$7:$J$22,"Y")/SUM(Supplier_Scorecard!$Q$7:$Q$22) -> 0.45857817 | D19: % | E19: 0.67 | F19: =IF(C19>=E19,"✔ On track","✖ Gap") -> ✖ Gap | G19: SBTi supplier engagement target
A20: 13 | B20: Average supplier ESG score (spend-weighted) | C20: =SUMPRODUCT(Supplier_Scorecard!$N$7:$N$22,Supplier_Scorecard!$P$7:$P$22)/SUM(Supplier_Scorecard!$P$7:$P$22) -> 55.313458 | D20: pts | E20: 60 | F20: =IF(C20>=E20,"✔ On track","✖ Gap") -> ✖ Gap | G20: 0-100
A21: 14 | B21: Average DQR of supplier PCFs | C21: =Supplier_Register!$O$22 -> 2.175 | D21: 1-5 | E21: 2.5 | F21: =IF(C21<=E21,"✔ On track","✖ Gap") -> ✔ On track | G21: PACT data quality rating
A22: 15 | B22: Suppliers rated D – escalation needed | C22: =COUNTIF(Supplier_Scorecard!$O$7:$O$22,"D*") -> 5 | D22: # | E22: 0 | F22: =IF(C22<=E22,"✔ On track","✖ Gap") -> ✖ Gap
A23: Circularity & data quality
A24: 16 | B24: Recycled fibre share in board | C24: =1 -> 1 | D24: % | E24: 1 | F24: =IF(C24>=E24,"✔ On track","✖ Gap") -> ✔ On track | G24: 100% RCP (incl. internal trim)
A25: 17 | B25: Internal trim recycled in closed loop | C25: =Company_Inputs!$B$16 -> 14318.182 | D25: t | E25: – | F25: Monitor | G25: FC trim returned to own mill
A26: 18 | B26: Recycled gypsum share | C26: =PCF_GypsumBoard!$C$8 -> 0.2 | D26: % | E26: 0.3 | F26: =IF(C26>=E26,"✔ On track","✖ Gap") -> ✖ Gap | G26: Substitutes natural & FGD gypsum
A27: 19 | B27: Mass balance deviation RCP (register vs. need) | C27: =ABS(GHG_Inventory!$G$76) -> 0.0013504978 | D27: % | E27: 0.02 | F27: =IF(C27<=E27,"✔ On track","✖ Gap") -> ✔ On track | G27: Data validation check
A28: Decarbonisation
A29: 20 | B29: Identified reduction potential | C29: =Decarbonisation!$F$15 -> 142271.19 | D29: t CO₂e/yr | E29: – | F29: Monitor | G29: Sum of levers
A30: 21 | B30: … as % of total inventory | C30: =Decarbonisation!$F$16 -> 0.27836358 | D30: % | E30: 0.2 | F30: =IF(C30>=E30,"✔ On track","✖ Gap") -> ✔ On track
B33: Emission split
B34: Scope | C34: t CO₂e
B35: Scope 1 | C35: =GHG_Inventory!$G$51 -> 202028.52
B36: Scope 2 (MB) | C36: =GHG_Inventory!$G$53 -> 107900.08
B37: Scope 3 | C37: =GHG_Inventory!$G$54 -> 201169.85

Sheet Company_Inputs
A1: Company Inputs – Reporting Year Activity Data
A2: Edit blue cells. Volumes are fictional but internally consistent (mass balance).
A4: Parameter | B4: Value | C4: Unit | D4: Source / comment
A5: Production
A6: Reporting year | B6: 2025 | D6: Text format
A7: Cartonboard sold to external converters | B7: 260000 | C7: t | D7: Sales statistics (fictional)
A8: Folding carton output | B8: 105000 | C8: t | D8: Converting plants output (fictional)
A9: Gypsum board output | B9: 45000 | C9: 1,000 m² | D9: i.e. 45 million m² (fictional)
A10: Gypsum board mass (12.5 mm) | B10: 8.5 | C10: kg/m² | D10: Typical standard board; product data sheet
A11: Board consumed by own folding carton plants | B11: =B8*PCF_FoldingCarton!$C$10/1000 -> 119318.18 | C11: t | D11: FC output × board input per t (PCF_FoldingCarton)
A12: Liner board consumed by own gypsum board plants | B12: =B9*PCF_GypsumBoard!$C$15/1000 -> 18000 | C12: t | D12: Gypsum output × liner kg per 1,000 m²
A13: Total cartonboard production | B13: =B7+B11+B12 -> 397318.18 | C13: t | D13: Mass balance
A14: Recovered paper mass balance (circularity)
A15: Gross recovered paper input | B15: =B13*PCF_Board!$C$5 -> 456915.91 | C15: t | D15: Board production × RCP input ratio
A16: Internal trim returned from FC plants (closed loop) | B16: =B11-B8 -> 14318.182 | C16: t | D16: Board input − FC output
A17: External recovered paper to be purchased | B17: =B15-B16 -> 442597.73 | C17: t | D17: Must reconcile with Supplier_Register
A18: Raw gypsum input (all sources) | B18: =B9*PCF_GypsumBoard!$C$5/1000 -> 405000 | C18: t | D18: Gypsum output × gypsum kg per 1,000 m²
A19: Other activity data
A20: Diesel – forklifts & yard vehicles | B20: 1500000 | C20: l | D20: Fuel cards / tank records
A21: Share of electricity covered by GoO / PPA | B21: 0.25 | C21: % | D21: Energy procurement contracts
A22: Indirect procurement spend (services, MRO, IT) | B22: 60000000 | C22: EUR | D22: ERP spend cube, excl. direct materials
A23: Capital expenditure | B23: 35000000 | C23: EUR | D23: Fixed asset additions
A24: Business travel | B24: 4200000 | C24: pkm | D24: Travel agency report
A25: Employees | B25: 2800 | C25: FTE | D25: HR
A26: Average one-way commute | B26: 18 | C26: km | D26: Employee mobility survey
A27: Working days per year | B27: 210 | C27: days | D27: HR
A28: Avg distance – external board collected by customers | B28: 200 | C28: km | D28: Logistics (Cat 9: customer-arranged)
A29: Avg distance – own outbound deliveries (FC & gypsum board) | B29: 300 | C29: km | D29: Logistics (Cat 4: paid by company)

Sheet Emission_Factors
A1: Emission Factor Library (kg CO₂e per unit, GWP100 AR6)
A2: Indicative values – replace with licensed / verified data before external reporting.
A4: EF ID | B4: Activity / material | C4: Unit | D4: kg CO₂e / unit | E4: Scope / category | F4: Source (indicative) | G4: Notes
A5: EF01 | B5: Natural gas – combustion | C5: kWh | D5: 0.201 | E5: Scope 1 | F5: UBA CO₂ emission factors (Hi basis) | G5: Combustion only; upstream in EF02
A6: EF02 | B6: Natural gas – upstream (WTT) | C6: kWh | D6: 0.03 | E6: Scope 3 Cat 3 | F6: DESNZ 2024 WTT factors (approx.)
A7: EF03 | B7: Grid electricity DE – location-based | C7: kWh | D7: 0.363 | E7: Scope 2 LB | F7: UBA electricity mix DE (provisional)
A8: EF04 | B8: Electricity – upstream & T&D losses | C8: kWh | D8: 0.045 | E8: Scope 3 Cat 3 | F8: DESNZ 2024 WTT + T&D (approx.)
A9: EF05 | B9: Renewable electricity (GoO / PPA) | C9: kWh | D9: 0 | E9: Scope 2 MB | F9: GHG Protocol Scope 2 Guidance | G9: Market-based, contractual instrument
A10: EF06 | B10: Road freight – articulated HGV (avg laden) | C10: tkm | D10: 0.095 | E10: Scope 3 Cat 4/9 | F10: DESNZ 2024 freighting goods
A11: EF07 | B11: Rail freight (electric/diesel mix) | C11: tkm | D11: 0.028 | E11: Scope 3 Cat 4 | F11: DESNZ 2024 / GLEC Framework
A12: EF08 | B12: Recovered paper – collection & sorting | C12: kg | D12: 0.015 | E12: Scope 3 Cat 1 | F12: CEPI framework, cut-off approach (approx.) | G12: RCP burden-free; only collection/sorting/baling
A13: EF09 | B13: Native starch (maize/wheat) | C13: kg | D13: 0.85 | E13: Scope 3 Cat 1 | F13: ecoinvent-type average (approx.)
A14: EF10 | B14: Calcium carbonate filler (GCC) | C14: kg | D14: 0.08 | E14: Scope 3 Cat 1 | F14: ecoinvent-type average (approx.)
A15: EF11 | B15: Process chemicals – generic | C15: kg | D15: 2 | E15: Scope 3 Cat 1 | F15: Conservative proxy | G15: Sizing, retention, biocides
A16: EF12 | B16: Offset printing ink | C16: kg | D16: 3.2 | E16: Scope 3 Cat 1 | F16: Industry average (approx.)
A17: EF13 | B17: Overprint varnish | C17: kg | D17: 2.5 | E17: Scope 3 Cat 1 | F17: Industry average (approx.)
A18: EF14 | B18: Dispersion adhesive | C18: kg | D18: 1.8 | E18: Scope 3 Cat 1 | F18: Industry average (approx.)
A19: EF15 | B19: LDPE stretch film | C19: kg | D19: 2.6 | E19: Scope 3 Cat 1 | F19: PlasticsEurope eco-profile (approx.)
A20: EF16 | B20: Natural gypsum (quarried) | C20: kg | D20: 0.004 | E20: Scope 3 Cat 1 | F20: EPD-type average (approx.)
A21: EF17 | B21: FGD gypsum (by-product of coal power) | C21: kg | D21: 0.002 | E21: Scope 3 Cat 1 | F21: By-product, economic allocation ≈ 0 | G21: Supply declining with coal phase-out
A22: EF18 | B22: Recycled gypsum (processing) | C22: kg | D22: 0.008 | E22: Scope 3 Cat 1 | F22: EPD-type average (approx.) | G22: Avoids landfill & primary extraction
A23: EF19 | B23: Glass fibre | C23: kg | D23: 1.6 | E23: Scope 3 Cat 1 | F23: ecoinvent-type average (approx.)
A24: EF20 | B24: Gypsum board additives / foaming agent | C24: kg | D24: 2.3 | E24: Scope 3 Cat 1 | F24: Conservative proxy
A25: EF21 | B25: Water supply & wastewater treatment | C25: m³ | D25: 0.3 | E25: Scope 3 Cat 5 | F25: Utility average (approx.)
A26: EF22 | B26: Rejects to incineration (fossil share) | C26: kg | D26: 0.6 | E26: Scope 3 Cat 5 | F26: Waste incineration, plastics fraction | G26: Pulper rejects: plastics, metals
A27: EF23 | B27: Indirect procurement – spend-based | C27: EUR | D27: 0.25 | E27: Scope 3 Cat 1 | F27: EEIO (EXIOBASE-type) average | G27: Use only as fallback
A28: EF24 | B28: Capital goods – spend-based | C28: EUR | D28: 0.35 | E28: Scope 3 Cat 2 | F28: EEIO (EXIOBASE-type) average
A29: EF25 | B29: Business travel – average (air/rail/car) | C29: pkm | D29: 0.15 | E29: Scope 3 Cat 6 | F29: DESNZ 2024 (blended)
A30: EF26 | B30: Employee commuting – average car | C30: pkm | D30: 0.17 | E30: Scope 3 Cat 7 | F30: DESNZ 2024
A31: EF27 | B31: Paperboard end-of-life (fossil, DE mix) | C31: kg | D31: 0.03 | E31: Scope 3 Cat 12 | F31: Recycling/incineration mix (approx.) | G31: Biogenic CO₂ excluded
A32: EF28 | B32: Gypsum board end-of-life (landfill/recycling) | C32: kg | D32: 0.01 | E32: Scope 3 Cat 12 | F32: EN 15804 C-modules (approx.)
A33: EF29 | B33: Diesel – combustion (mobile) | C33: l | D33: 2.65 | E33: Scope 1 | F33: UBA / DESNZ 2024 | G33: Forklifts, yard vehicles
A34: EF30 | B34: Diesel – upstream (WTT) | C34: l | D34: 0.62 | E34: Scope 3 Cat 3 | F34: DESNZ 2024 WTT
A35: EF31 | B35: Residual mix DE – market-based | C35: kWh | D35: 0.62 | E35: Scope 2 MB | F35: AIB European Residual Mix (approx.)
A36: EF32 | B36: Biomethane – combustion + upstream (fossil) | C36: kWh | D36: 0.03 | E36: Scope 1 | F36: Indicative; biogenic CO₂ excluded | G36: Used in Decarbonisation

Sheet PCF_Board
A1: PCF – 100% Recycled Cartonboard (FU: 1 t, cradle-to-gate)
A2: ISO 14067 / CEPI framework · cut-off approach for recovered paper · fossil GHG only, biogenic carbon as memo item
A4: Parameters
B5: Recovered paper input ratio (t RCP / t board) | C5: 1.15 | D5: t/t | J5: Mill yield incl. moisture & rejects; production data
B6: Avg RCP transport distance to mill | C6: 150 | D6: km | J6: Weighted from Supplier_Register logistics data
B7: Biogenic carbon content of board (kg C / kg) | C7: 0.4 | D7: kg/kg | J7: Typical fibre carbon content (memo only)
A9: Stage | B9: Input / process | C9: Quantity per FU | D9: Unit | E9: EF ID | F9: EF (kg CO₂e / unit) | G9: kg CO₂e per FU | H9: Share | I9: Company scope | J9: Data source / quality note
A10: A1 Raw materials | B10: Recovered paper (collection & sorting) | C10: =1000*$C$5 -> 1150 | D10: kg | E10: EF08 | F10: =VLOOKUP(E10,Emission_Factors!$A:$D,4,FALSE()) -> 0.015 | G10: =C10*F10 -> 17.25 | H10: =IFERROR(G10/$G$21,0) -> 0.024067389 | I10: Scope 3 Cat 1 | J10: Burden-free fibre; secondary EF – request supplier data
A11: A1 Raw materials | B11: Native starch (surface & wet-end) | C11: 40 | D11: kg | E11: EF09 | F11: =VLOOKUP(E11,Emission_Factors!$A:$D,4,FALSE()) -> 0.85 | G11: =C11*F11 -> 34 | H11: =IFERROR(G11/$G$21,0) -> 0.047437172 | I11: Scope 3 Cat 1 | J11: Supplier PCF available (see register)
A12: A1 Raw materials | B12: Calcium carbonate filler | C12: 30 | D12: kg | E12: EF10 | F12: =VLOOKUP(E12,Emission_Factors!$A:$D,4,FALSE()) -> 0.08 | G12: =C12*F12 -> 2.4 | H12: =IFERROR(G12/$G$21,0) -> 0.0033485063 | I12: Scope 3 Cat 1
A13: A1 Raw materials | B13: Process chemicals | C13: 10 | D13: kg | E13: EF11 | F13: =VLOOKUP(E13,Emission_Factors!$A:$D,4,FALSE()) -> 2 | G13: =C13*F13 -> 20 | H13: =IFERROR(G13/$G$21,0) -> 0.027904219 | I13: Scope 3 Cat 1 | J13: Proxy – data gap
A14: A2 Transport | B14: Inbound transport recovered paper | C14: =$C$5*$C$6 -> 172.5 | D14: tkm | E14: EF06 | F14: =VLOOKUP(E14,Emission_Factors!$A:$D,4,FALSE()) -> 0.095 | G14: =C14*F14 -> 16.3875 | H14: =IFERROR(G14/$G$21,0) -> 0.022864019 | I14: Scope 3 Cat 4 | J14: t × km
A15: A3 Manufacturing | B15: Natural gas – steam & drying (CHP/boiler) | C15: 1700 | D15: kWh | E15: EF01 | F15: =VLOOKUP(E15,Emission_Factors!$A:$D,4,FALSE()) -> 0.201 | G15: =C15*F15 -> 341.7 | H15: =IFERROR(G15/$G$21,0) -> 0.47674358 | I15: Scope 1 | J15: Metered, mill energy management (ISO 50001)
A16: A3 Manufacturing | B16: Natural gas – upstream | C16: =$C$15 -> 1700 | D16: kWh | E16: EF02 | F16: =VLOOKUP(E16,Emission_Factors!$A:$D,4,FALSE()) -> 0.03 | G16: =C16*F16 -> 51 | H16: =IFERROR(G16/$G$21,0) -> 0.071155758 | I16: Scope 3 Cat 3
A17: A3 Manufacturing | B17: Grid electricity (location-based) | C17: 450 | D17: kWh | E17: EF03 | F17: =VLOOKUP(E17,Emission_Factors!$A:$D,4,FALSE()) -> 0.363 | G17: =C17*F17 -> 163.35 | H17: =IFERROR(G17/$G$21,0) -> 0.22790771 | I17: Scope 2 | J17: Metered; market-based see GHG_Inventory
A18: A3 Manufacturing | B18: Electricity – upstream & losses | C18: =$C$17 -> 450 | D18: kWh | E18: EF04 | F18: =VLOOKUP(E18,Emission_Factors!$A:$D,4,FALSE()) -> 0.045 | G18: =C18*F18 -> 20.25 | H18: =IFERROR(G18/$G$21,0) -> 0.028253022 | I18: Scope 3 Cat 3
A19: A3 Manufacturing | B19: Water & wastewater treatment | C19: 8 | D19: m³ | E19: EF21 | F19: =VLOOKUP(E19,Emission_Factors!$A:$D,4,FALSE()) -> 0.3 | G19: =C19*F19 -> 2.4 | H19: =IFERROR(G19/$G$21,0) -> 0.0033485063 | I19: Scope 3 Cat 5
A20: A3 Manufacturing | B20: Pulper rejects to incineration | C20: 80 | D20: kg | E20: EF22 | F20: =VLOOKUP(E20,Emission_Factors!$A:$D,4,FALSE()) -> 0.6 | G20: =C20*F20 -> 48 | H20: =IFERROR(G20/$G$21,0) -> 0.066970125 | I20: Scope 3 Cat 5 | J20: Plastics/metal fraction from RCP
A21: TOTAL PCF (kg CO₂e / t board) | G21: =SUM(G10:G20) -> 716.7375 | H21: =SUM(H10:H20) -> 1
A23: Memo: biogenic carbon stored | B23: kg CO₂ removed & stored in 1 t board (ISO 14067 §7.2, reported separately) | G23: =-1000*$C$7*44/12 -> -1466.6667
A24: PCF per kg | B24: kg CO₂e / kg board (used downstream in FC & gypsum board) | G24: =$G$21/1000 -> 0.7167375
A26: Hotspot summary by life-cycle stage
A27: Stage | B27: kg CO₂e | C27: Share
A28: A1 Raw materials | B28: =SUMIF($A$10:$A$20,A28,$G$10:$G$20) -> 73.65 | C28: =IFERROR(B28/$G$21,0) -> 0.10275729
A29: A2 Transport | B29: =SUMIF($A$10:$A$20,A29,$G$10:$G$20) -> 16.3875 | C29: =IFERROR(B29/$G$21,0) -> 0.022864019
A30: A3 Manufacturing | B30: =SUMIF($A$10:$A$20,A30,$G$10:$G$20) -> 626.7 | C30: =IFERROR(B30/$G$21,0) -> 0.8743787

Sheet PCF_FoldingCarton
A1: PCF – Printed Folding Carton (FU: 1 t, cradle-to-gate + optional distribution)
A2: Board input from own mill (linked to PCF_Board) · trim waste returned to mill as RCP (closed loop, cut-off)
A4: Parameters
B5: Trim / die-cut waste rate (of board input) | C5: 0.12 | D5: % | J5: Converting plant waste statistics
B6: Board transport mill → converting plant | C6: 250 | D6: km | J6: Internal logistics
B7: PCF recycled cartonboard (kg CO₂e/kg) | C7: =PCF_Board!$G$24 -> 0.7167375 | D7: kg/kg | J7: Link to PCF_Board
A9: Stage | B9: Input / process | C9: Quantity per FU | D9: Unit | E9: EF ID | F9: EF (kg CO₂e / unit) | G9: kg CO₂e per FU | H9: Share | I9: Company scope | J9: Data source / quality note
A10: A1 Raw materials | B10: Recycled cartonboard (own mill) | C10: =1000/(1-$C$5) -> 1136.3636 | D10: kg | E10: link | F10: =PCF_Board!$G$24 -> 0.7167375 | G10: =C10*F10 -> 814.47443 | H10: =IFERROR(G10/$G$21,0) -> 0.770853 | I10: Scope 1/2/3 (internal) | J10: Primary data – own mill PCF
A11: A1 Raw materials | B11: Offset printing inks | C11: 15 | D11: kg | E11: EF12 | F11: =VLOOKUP(E11,Emission_Factors!$A:$D,4,FALSE()) -> 3.2 | G11: =C11*F11 -> 48 | H11: =IFERROR(G11/$G$21,0) -> 0.045429227 | I11: Scope 3 Cat 1 | J11: Supplier PCF available
A12: A1 Raw materials | B12: Overprint varnish | C12: 8 | D12: kg | E12: EF13 | F12: =VLOOKUP(E12,Emission_Factors!$A:$D,4,FALSE()) -> 2.5 | G12: =C12*F12 -> 20 | H12: =IFERROR(G12/$G$21,0) -> 0.018928845 | I12: Scope 3 Cat 1
A13: A1 Raw materials | B13: Dispersion adhesive (gluing) | C13: 5 | D13: kg | E13: EF14 | F13: =VLOOKUP(E13,Emission_Factors!$A:$D,4,FALSE()) -> 1.8 | G13: =C13*F13 -> 9 | H13: =IFERROR(G13/$G$21,0) -> 0.0085179801 | I13: Scope 3 Cat 1
A14: A1 Raw materials | B14: Packaging – LDPE stretch film | C14: 6 | D14: kg | E14: EF15 | F14: =VLOOKUP(E14,Emission_Factors!$A:$D,4,FALSE()) -> 2.6 | G14: =C14*F14 -> 15.6 | H14: =IFERROR(G14/$G$21,0) -> 0.014764499 | I14: Scope 3 Cat 1
A15: A2 Transport | B15: Board transport mill → plant | C15: =$C$10/1000*$C$6 -> 284.09091 | D15: tkm | E15: EF06 | F15: =VLOOKUP(E15,Emission_Factors!$A:$D,4,FALSE()) -> 0.095 | G15: =C15*F15 -> 26.988636 | H15: =IFERROR(G15/$G$21,0) -> 0.025543185 | I15: Scope 3 Cat 4 | J15: t × km
A16: A3 Manufacturing | B16: Natural gas – heating & ink drying | C16: 80 | D16: kWh | E16: EF01 | F16: =VLOOKUP(E16,Emission_Factors!$A:$D,4,FALSE()) -> 0.201 | G16: =C16*F16 -> 16.08 | H16: =IFERROR(G16/$G$21,0) -> 0.015218791 | I16: Scope 1 | J16: Metered
A17: A3 Manufacturing | B17: Natural gas – upstream | C17: =$C$16 -> 80 | D17: kWh | E17: EF02 | F17: =VLOOKUP(E17,Emission_Factors!$A:$D,4,FALSE()) -> 0.03 | G17: =C17*F17 -> 2.4 | H17: =IFERROR(G17/$G$21,0) -> 0.0022714614 | I17: Scope 3 Cat 3
A18: A3 Manufacturing | B18: Electricity – printing, die-cutting, gluing | C18: 250 | D18: kWh | E18: EF03 | F18: =VLOOKUP(E18,Emission_Factors!$A:$D,4,FALSE()) -> 0.363 | G18: =C18*F18 -> 90.75 | H18: =IFERROR(G18/$G$21,0) -> 0.085889633 | I18: Scope 2 | J18: Metered
A19: A3 Manufacturing | B19: Electricity – upstream & losses | C19: =$C$18 -> 250 | D19: kWh | E19: EF04 | F19: =VLOOKUP(E19,Emission_Factors!$A:$D,4,FALSE()) -> 0.045 | G19: =C19*F19 -> 11.25 | H19: =IFERROR(G19/$G$21,0) -> 0.010647475 | I19: Scope 3 Cat 3
A20: A3 Manufacturing | B20: Trim waste → own mill as RCP (closed loop) | C20: =$C$10-1000 -> 136.36364 | D20: kg | E20: EF08 | F20: =VLOOKUP(E20,Emission_Factors!$A:$D,4,FALSE()) -> 0.015 | G20: =C20*F20 -> 2.0454545 | H20: =IFERROR(G20/$G$21,0) -> 0.0019359046 | I20: Scope 3 Cat 1 | J20: Only sorting/baling allocated (cut-off)
A21: PCF CRADLE-TO-GATE (kg CO₂e / t) | G21: =SUM(G10:G20) -> 1056.5885 | H21: =SUM(H10:H20) -> 1
A22: Optional A4 | B22: Distribution to customer (1 t × avg outbound distance) | C22: =Company_Inputs!$B$29 -> 300 | D22: tkm | E22: EF06 | F22: =VLOOKUP(E22,Emission_Factors!$A:$D,4,FALSE()) -> 0.095 | G22: =C22*F22 -> 28.5
A23: PCF CRADLE-TO-CUSTOMER | G23: =$G$21+G22 -> 1085.0885
A24: Memo: biogenic carbon | B24: kg CO₂ stored in 1 t carton | G24: =-1000*PCF_Board!$C$7*44/12 -> -1466.6667
A26: Hotspot summary by life-cycle stage
A27: Stage | B27: kg CO₂e | C27: Share
A28: A1 Raw materials | B28: =SUMIF($A$10:$A$20,A28,$G$10:$G$20) -> 907.07443 | C28: =IFERROR(B28/$G$21,0) -> 0.85849355
A29: A2 Transport | B29: =SUMIF($A$10:$A$20,A29,$G$10:$G$20) -> 26.988636 | C29: =IFERROR(B29/$G$21,0) -> 0.025543185
A30: A3 Manufacturing | B30: =SUMIF($A$10:$A$20,A30,$G$10:$G$20) -> 122.52545 | C30: =IFERROR(B30/$G$21,0) -> 0.11596326

Sheet PCF_GypsumBoard
A1: PCF – Gypsum Plasterboard 12.5 mm (calculated per 1,000 m², declared per m²)
A2: EN 15804 modules A1-A3 · liner paper from own recycled board mill (linked to PCF_Board)
A4: Parameters
B5: Raw gypsum input (dihydrate) per 1,000 m² | C5: 9000 | D5: kg | J5: Recipe; water of crystallisation released in calcination
B6: Share natural gypsum | C6: 0.5 | D6: % | J6: Procurement mix
B7: Share FGD gypsum | C7: 0.3 | D7: % | J7: Procurement mix – declining (coal exit)
B8: Share recycled gypsum | C8: =1-C6-C7 -> 0.2 | D8: % | J8: Remainder
B9: Avg gypsum transport distance | C9: 80 | D9: km | J9: Quarry / power plant / recycler
A11: Stage | B11: Input / process | C11: Quantity per FU | D11: Unit | E11: EF ID | F11: EF (kg CO₂e / unit) | G11: kg CO₂e per FU | H11: Share | I11: Company scope | J11: Data source / quality note
A12: A1 Raw materials | B12: Natural gypsum | C12: =$C$5*$C$6 -> 4500 | D12: kg | E12: EF16 | F12: =VLOOKUP(E12,Emission_Factors!$A:$D,4,FALSE()) -> 0.004 | G12: =C12*F12 -> 18 | H12: =IFERROR(G12/$G$27,0) -> 0.0079547639 | I12: Scope 3 Cat 1
A13: A1 Raw materials | B13: FGD gypsum | C13: =$C$5*$C$7 -> 2700 | D13: kg | E13: EF17 | F13: =VLOOKUP(E13,Emission_Factors!$A:$D,4,FALSE()) -> 0.002 | G13: =C13*F13 -> 5.4 | H13: =IFERROR(G13/$G$27,0) -> 0.0023864292 | I13: Scope 3 Cat 1
A14: A1 Raw materials | B14: Recycled gypsum | C14: =$C$5*$C$8 -> 1800 | D14: kg | E14: EF18 | F14: =VLOOKUP(E14,Emission_Factors!$A:$D,4,FALSE()) -> 0.008 | G14: =C14*F14 -> 14.4 | H14: =IFERROR(G14/$G$27,0) -> 0.0063638111 | I14: Scope 3 Cat 1
A15: A1 Raw materials | B15: Liner board (own recycled mill) | C15: 400 | D15: kg | E15: link | F15: =PCF_Board!$G$24 -> 0.7167375 | G15: =C15*F15 -> 286.695 | H15: =IFERROR(G15/$G$27,0) -> 0.1266995 | I15: Scope 1/2/3 (internal) | J15: Primary data – own mill PCF; ~200 g/m² per face
A16: A1 Raw materials | B16: Starch (core bonding) | C16: 30 | D16: kg | E16: EF09 | F16: =VLOOKUP(E16,Emission_Factors!$A:$D,4,FALSE()) -> 0.85 | G16: =C16*F16 -> 25.5 | H16: =IFERROR(G16/$G$27,0) -> 0.011269249 | I16: Scope 3 Cat 1
A17: A1 Raw materials | B17: Glass fibre | C17: 10 | D17: kg | E17: EF19 | F17: =VLOOKUP(E17,Emission_Factors!$A:$D,4,FALSE()) -> 1.6 | G17: =C17*F17 -> 16 | H17: =IFERROR(G17/$G$27,0) -> 0.0070709013 | I17: Scope 3 Cat 1
A18: A1 Raw materials | B18: Additives & foaming agent | C18: 5 | D18: kg | E18: EF20 | F18: =VLOOKUP(E18,Emission_Factors!$A:$D,4,FALSE()) -> 2.3 | G18: =C18*F18 -> 11.5 | H18: =IFERROR(G18/$G$27,0) -> 0.0050822103 | I18: Scope 3 Cat 1 | J18: Proxy – data gap
A19: A1 Raw materials | B19: Packaging – LDPE film | C19: 5 | D19: kg | E19: EF15 | F19: =VLOOKUP(E19,Emission_Factors!$A:$D,4,FALSE()) -> 2.6 | G19: =C19*F19 -> 13 | H19: =IFERROR(G19/$G$27,0) -> 0.0057451073 | I19: Scope 3 Cat 1
A20: A2 Transport | B20: Gypsum inbound transport | C20: =$C$5/1000*$C$9 -> 720 | D20: tkm | E20: EF06 | F20: =VLOOKUP(E20,Emission_Factors!$A:$D,4,FALSE()) -> 0.095 | G20: =C20*F20 -> 68.4 | H20: =IFERROR(G20/$G$27,0) -> 0.030228103 | I20: Scope 3 Cat 4
A21: A2 Transport | B21: Liner board transport mill → plant | C21: 120 | D21: tkm | E21: EF06 | F21: =VLOOKUP(E21,Emission_Factors!$A:$D,4,FALSE()) -> 0.095 | G21: =C21*F21 -> 11.4 | H21: =IFERROR(G21/$G$27,0) -> 0.0050380171 | I21: Scope 3 Cat 4 | J21: 0.4 t × 300 km
A22: A3 Manufacturing | B22: Natural gas – calcination | C22: 2200 | D22: kWh | E22: EF01 | F22: =VLOOKUP(E22,Emission_Factors!$A:$D,4,FALSE()) -> 0.201 | G22: =C22*F22 -> 442.2 | H22: =IFERROR(G22/$G$27,0) -> 0.19542203 | I22: Scope 1 | J22: Metered
A23: A3 Manufacturing | B23: Natural gas – board drying | C23: 4500 | D23: kWh | E23: EF01 | F23: =VLOOKUP(E23,Emission_Factors!$A:$D,4,FALSE()) -> 0.201 | G23: =C23*F23 -> 904.5 | H23: =IFERROR(G23/$G$27,0) -> 0.39972689 | I23: Scope 1 | J23: Metered – main hotspot
A24: A3 Manufacturing | B24: Natural gas – upstream | C24: =$C$22+$C$23 -> 6700 | D24: kWh | E24: EF02 | F24: =VLOOKUP(E24,Emission_Factors!$A:$D,4,FALSE()) -> 0.03 | G24: =C24*F24 -> 201 | H24: =IFERROR(G24/$G$27,0) -> 0.088828197 | I24: Scope 3 Cat 3
A25: A3 Manufacturing | B25: Electricity | C25: 600 | D25: kWh | E25: EF03 | F25: =VLOOKUP(E25,Emission_Factors!$A:$D,4,FALSE()) -> 0.363 | G25: =C25*F25 -> 217.8 | H25: =IFERROR(G25/$G$27,0) -> 0.096252643 | I25: Scope 2 | J25: Metered
A26: A3 Manufacturing | B26: Electricity – upstream & losses | C26: =$C$25 -> 600 | D26: kWh | E26: EF04 | F26: =VLOOKUP(E26,Emission_Factors!$A:$D,4,FALSE()) -> 0.045 | G26: =C26*F26 -> 27 | H26: =IFERROR(G26/$G$27,0) -> 0.011932146 | I26: Scope 3 Cat 3
A27: TOTAL (kg CO₂e / 1,000 m²) | G27: =SUM(G12:G26) -> 2262.795 | H27: =SUM(H12:H26) -> 1
A28: Declared unit | B28: kg CO₂e per m² gypsum board | G28: =$G$27/1000 -> 2.262795
B29: kg CO₂e per t gypsum board | G29: =G28/Company_Inputs!$B$10*1000 -> 266.21118
A31: Hotspot summary by life-cycle stage
A32: Stage | B32: kg CO₂e | C32: Share
A33: A1 Raw materials | B33: =SUMIF($A$12:$A$26,A33,$G$12:$G$26) -> 390.495 | C33: =IFERROR(B33/$G$27,0) -> 0.17257197
A34: A2 Transport | B34: =SUMIF($A$12:$A$26,A34,$G$12:$G$26) -> 79.8 | C34: =IFERROR(B34/$G$27,0) -> 0.03526612
A35: A3 Manufacturing | B35: =SUMIF($A$12:$A$26,A35,$G$12:$G$26) -> 1792.5 | C35: =IFERROR(B35/$G$27,0) -> 0.79216191

Sheet Supplier_Register
A1: Supplier Register – Volumes, Supplier-Specific PCFs & PACT Data Quality (Scope 3 Cat 1)
A2: Supplier PCF is used only if provided AND DQR ≤ threshold; otherwise secondary EF. Suppliers are fictional.
A3: DQR acceptance threshold | D3: 3 | E3: ← PACT DQR scale 1 (very good) – 5 (very poor)
A5: ID | B5: Supplier (fictional) | C5: Country | D5: Material | E5: Default EF ID | F5: Volume (t) | G5: Spend (EUR k) | H5: Supplier PCF (kg CO₂e/kg) | I5: PCF standard | J5: TeR | K5: GeR | L5: TiR | M5: Compl. | N5: Reliab. | O5: DQR | P5: Default EF | Q5: Applied EF | R5: Data basis | S5: Emissions (t CO₂e) | T5: Emissions w/ default (t CO₂e) | U5: Δ vs default (t CO₂e) | V5: Next action
A6: S01 | B6: Recycling Partner North | C6: DE | D6: Recovered paper | E6: EF08 | F6: 160000 | G6: 19200 | H6: 0.012 | I6: ISO 14067 | J6: 2 | K6: 1 | L6: 2 | M6: 3 | N6: 2 | O6: =IF(H6="","",AVERAGE(J6:N6)) -> 2 | P6: =VLOOKUP(E6,Emission_Factors!$A:$D,4,FALSE()) -> 0.015 | Q6: =IF(AND(H6<>"",O6<>""),IF(O6<=$D$3,H6,P6),P6) -> 0.012 | R6: =IF(H6="","Secondary (no PCF)",IF(O6<=$D$3,"Supplier-specific","Secondary (DQR fail)")) -> Supplier-specific | S6: =F6*Q6 -> 1920 | T6: =F6*P6 -> 2400 | U6: =S6-T6 -> -480 | V6: =IF(R6="Supplier-specific","Annual PCF update via PACT",IF(R6="Secondary (DQR fail)","Improve data quality: primary energy data","Send PCF request + survey")) -> Annual PCF update via PACT
A7: S02 | B7: Recycling Partner South | C7: DE | D7: Recovered paper | E7: EF08 | F7: 135000 | G7: 16200 | O7: =IF(H7="","",AVERAGE(J7:N7)) | P7: =VLOOKUP(E7,Emission_Factors!$A:$D,4,FALSE()) -> 0.015 | Q7: =IF(AND(H7<>"",O7<>""),IF(O7<=$D$3,H7,P7),P7) -> 0.015 | R7: =IF(H7="","Secondary (no PCF)",IF(O7<=$D$3,"Supplier-specific","Secondary (DQR fail)")) -> Secondary (no PCF) | S7: =F7*Q7 -> 2025 | T7: =F7*P7 -> 2025 | U7: =S7-T7 -> 0 | V7: =IF(R7="Supplier-specific","Annual PCF update via PACT",IF(R7="Secondary (DQR fail)","Improve data quality: primary energy data","Send PCF request + survey")) -> Send PCF request + survey
A8: S03 | B8: Municipal Paper Collection Pool | C8: DE | D8: Recovered paper | E8: EF08 | F8: 92000 | G8: 10100 | O8: =IF(H8="","",AVERAGE(J8:N8)) | P8: =VLOOKUP(E8,Emission_Factors!$A:$D,4,FALSE()) -> 0.015 | Q8: =IF(AND(H8<>"",O8<>""),IF(O8<=$D$3,H8,P8),P8) -> 0.015 | R8: =IF(H8="","Secondary (no PCF)",IF(O8<=$D$3,"Supplier-specific","Secondary (DQR fail)")) -> Secondary (no PCF) | S8: =F8*Q8 -> 1380 | T8: =F8*P8 -> 1380 | U8: =S8-T8 -> 0 | V8: =IF(R8="Supplier-specific","Annual PCF update via PACT",IF(R8="Secondary (DQR fail)","Improve data quality: primary energy data","Send PCF request + survey")) -> Send PCF request + survey
A9: S04 | B9: RCP Trader Benelux | C9: NL | D9: Recovered paper | E9: EF08 | F9: 55000 | G9: 6900 | H9: 0.02 | I9: Own method | J9: 4 | K9: 3 | L9: 3 | M9: 4 | N9: 4 | O9: =IF(H9="","",AVERAGE(J9:N9)) -> 3.6 | P9: =VLOOKUP(E9,Emission_Factors!$A:$D,4,FALSE()) -> 0.015 | Q9: =IF(AND(H9<>"",O9<>""),IF(O9<=$D$3,H9,P9),P9) -> 0.015 | R9: =IF(H9="","Secondary (no PCF)",IF(O9<=$D$3,"Supplier-specific","Secondary (DQR fail)")) -> Secondary (DQR fail) | S9: =F9*Q9 -> 825 | T9: =F9*P9 -> 825 | U9: =S9-T9 -> 0 | V9: =IF(R9="Supplier-specific","Annual PCF update via PACT",IF(R9="Secondary (DQR fail)","Improve data quality: primary energy data","Send PCF request + survey")) -> Improve data quality: primary energy data
A10: S05 | B10: Starch Mill Central | C10: DE | D10: Native starch | E10: EF09 | F10: 17200 | G10: 8600 | H10: 0.62 | I10: PACT v3 | J10: 1 | K10: 2 | L10: 1 | M10: 2 | N10: 3 | O10: =IF(H10="","",AVERAGE(J10:N10)) -> 1.8 | P10: =VLOOKUP(E10,Emission_Factors!$A:$D,4,FALSE()) -> 0.85 | Q10: =IF(AND(H10<>"",O10<>""),IF(O10<=$D$3,H10,P10),P10) -> 0.62 | R10: =IF(H10="","Secondary (no PCF)",IF(O10<=$D$3,"Supplier-specific","Secondary (DQR fail)")) -> Supplier-specific | S10: =F10*Q10 -> 10664 | T10: =F10*P10 -> 14620 | U10: =S10-T10 -> -3956 | V10: =IF(R10="Supplier-specific","Annual PCF update via PACT",IF(R10="Secondary (DQR fail)","Improve data quality: primary energy data","Send PCF request + survey")) -> Annual PCF update via PACT
A11: S06 | B11: Mineral Fillers Alpine | C11: AT | D11: Calcium carbonate | E11: EF10 | F11: 11900 | G11: 1500 | H11: 0.06 | I11: ISO 14067 | J11: 2 | K11: 2 | L11: 3 | M11: 2 | N11: 3 | O11: =IF(H11="","",AVERAGE(J11:N11)) -> 2.4 | P11: =VLOOKUP(E11,Emission_Factors!$A:$D,4,FALSE()) -> 0.08 | Q11: =IF(AND(H11<>"",O11<>""),IF(O11<=$D$3,H11,P11),P11) -> 0.06 | R11: =IF(H11="","Secondary (no PCF)",IF(O11<=$D$3,"Supplier-specific","Secondary (DQR fail)")) -> Supplier-specific | S11: =F11*Q11 -> 714 | T11: =F11*P11 -> 952 | U11: =S11-T11 -> -238 | V11: =IF(R11="Supplier-specific","Annual PCF update via PACT",IF(R11="Secondary (DQR fail)","Improve data quality: primary energy data","Send PCF request + survey")) -> Annual PCF update via PACT
A12: S07 | B12: ProcessChem Solutions | C12: DE | D12: Process chemicals | E12: EF11 | F12: 4000 | G12: 9200 | O12: =IF(H12="","",AVERAGE(J12:N12)) | P12: =VLOOKUP(E12,Emission_Factors!$A:$D,4,FALSE()) -> 2 | Q12: =IF(AND(H12<>"",O12<>""),IF(O12<=$D$3,H12,P12),P12) -> 2 | R12: =IF(H12="","Secondary (no PCF)",IF(O12<=$D$3,"Supplier-specific","Secondary (DQR fail)")) -> Secondary (no PCF) | S12: =F12*Q12 -> 8000 | T12: =F12*P12 -> 8000 | U12: =S12-T12 -> 0 | V12: =IF(R12="Supplier-specific","Annual PCF update via PACT",IF(R12="Secondary (DQR fail)","Improve data quality: primary energy data","Send PCF request + survey")) -> Send PCF request + survey
A13: S08 | B13: PrintInk Europe | C13: DE | D13: Printing ink | E13: EF12 | F13: 1575 | G13: 7900 | H13: 2.7 | I13: PACT v3 | J13: 2 | K13: 2 | L13: 1 | M13: 2 | N13: 2 | O13: =IF(H13="","",AVERAGE(J13:N13)) -> 1.8 | P13: =VLOOKUP(E13,Emission_Factors!$A:$D,4,FALSE()) -> 3.2 | Q13: =IF(AND(H13<>"",O13<>""),IF(O13<=$D$3,H13,P13),P13) -> 2.7 | R13: =IF(H13="","Secondary (no PCF)",IF(O13<=$D$3,"Supplier-specific","Secondary (DQR fail)")) -> Supplier-specific | S13: =F13*Q13 -> 4252.5 | T13: =F13*P13 -> 5040 | U13: =S13-T13 -> -787.5 | V13: =IF(R13="Supplier-specific","Annual PCF update via PACT",IF(R13="Secondary (DQR fail)","Improve data quality: primary energy data","Send PCF request + survey")) -> Annual PCF update via PACT
A14: S09 | B14: CoatTech Varnish | C14: IT | D14: Varnish | E14: EF13 | F14: 840 | G14: 3400 | O14: =IF(H14="","",AVERAGE(J14:N14)) | P14: =VLOOKUP(E14,Emission_Factors!$A:$D,4,FALSE()) -> 2.5 | Q14: =IF(AND(H14<>"",O14<>""),IF(O14<=$D$3,H14,P14),P14) -> 2.5 | R14: =IF(H14="","Secondary (no PCF)",IF(O14<=$D$3,"Supplier-specific","Secondary (DQR fail)")) -> Secondary (no PCF) | S14: =F14*Q14 -> 2100 | T14: =F14*P14 -> 2100 | U14: =S14-T14 -> 0 | V14: =IF(R14="Supplier-specific","Annual PCF update via PACT",IF(R14="Secondary (DQR fail)","Improve data quality: primary energy data","Send PCF request + survey")) -> Send PCF request + survey
A15: S10 | B15: BondWell Adhesives | C15: DE | D15: Adhesive | E15: EF14 | F15: 525 | G15: 1600 | H15: 1.5 | I15: ISO 14067 | J15: 2 | K15: 2 | L15: 2 | M15: 3 | N15: 3 | O15: =IF(H15="","",AVERAGE(J15:N15)) -> 2.4 | P15: =VLOOKUP(E15,Emission_Factors!$A:$D,4,FALSE()) -> 1.8 | Q15: =IF(AND(H15<>"",O15<>""),IF(O15<=$D$3,H15,P15),P15) -> 1.5 | R15: =IF(H15="","Secondary (no PCF)",IF(O15<=$D$3,"Supplier-specific","Secondary (DQR fail)")) -> Supplier-specific | S15: =F15*Q15 -> 787.5 | T15: =F15*P15 -> 945 | U15: =S15-T15 -> -157.5 | V15: =IF(R15="Supplier-specific","Annual PCF update via PACT",IF(R15="Secondary (DQR fail)","Improve data quality: primary energy data","Send PCF request + survey")) -> Annual PCF update via PACT
A16: S11 | B16: FilmPack Poly | C16: PL | D16: Stretch film | E16: EF15 | F16: 855 | G16: 1700 | O16: =IF(H16="","",AVERAGE(J16:N16)) | P16: =VLOOKUP(E16,Emission_Factors!$A:$D,4,FALSE()) -> 2.6 | Q16: =IF(AND(H16<>"",O16<>""),IF(O16<=$D$3,H16,P16),P16) -> 2.6 | R16: =IF(H16="","Secondary (no PCF)",IF(O16<=$D$3,"Supplier-specific","Secondary (DQR fail)")) -> Secondary (no PCF) | S16: =F16*Q16 -> 2223 | T16: =F16*P16 -> 2223 | U16: =S16-T16 -> 0 | V16: =IF(R16="Supplier-specific","Annual PCF update via PACT",IF(R16="Secondary (DQR fail)","Improve data quality: primary energy data","Send PCF request + survey")) -> Send PCF request + survey
A17: S12 | B17: Gypsum Quarry Harz | C17: DE | D17: Natural gypsum | E17: EF16 | F17: 202500 | G17: 4100 | H17: 0.005 | I17: EPD EN 15804 | J17: 2 | K17: 1 | L17: 2 | M17: 2 | N17: 1 | O17: =IF(H17="","",AVERAGE(J17:N17)) -> 1.6 | P17: =VLOOKUP(E17,Emission_Factors!$A:$D,4,FALSE()) -> 0.004 | Q17: =IF(AND(H17<>"",O17<>""),IF(O17<=$D$3,H17,P17),P17) -> 0.005 | R17: =IF(H17="","Secondary (no PCF)",IF(O17<=$D$3,"Supplier-specific","Secondary (DQR fail)")) -> Supplier-specific | S17: =F17*Q17 -> 1012.5 | T17: =F17*P17 -> 810 | U17: =S17-T17 -> 202.5 | V17: =IF(R17="Supplier-specific","Annual PCF update via PACT",IF(R17="Secondary (DQR fail)","Improve data quality: primary energy data","Send PCF request + survey")) -> Annual PCF update via PACT
A18: S13 | B18: Power Plant By-Products | C18: DE | D18: FGD gypsum | E18: EF17 | F18: 121500 | G18: 1800 | O18: =IF(H18="","",AVERAGE(J18:N18)) | P18: =VLOOKUP(E18,Emission_Factors!$A:$D,4,FALSE()) -> 0.002 | Q18: =IF(AND(H18<>"",O18<>""),IF(O18<=$D$3,H18,P18),P18) -> 0.002 | R18: =IF(H18="","Secondary (no PCF)",IF(O18<=$D$3,"Supplier-specific","Secondary (DQR fail)")) -> Secondary (no PCF) | S18: =F18*Q18 -> 243 | T18: =F18*P18 -> 243 | U18: =S18-T18 -> 0 | V18: =IF(R18="Supplier-specific","Annual PCF update via PACT",IF(R18="Secondary (DQR fail)","Improve data quality: primary energy data","Send PCF request + survey")) -> Send PCF request + survey
A19: S14 | B19: Gypsum Recycling West | C19: DE | D19: Recycled gypsum | E19: EF18 | F19: 81000 | G19: 2400 | H19: 0.007 | I19: ISO 14067 | J19: 2 | K19: 1 | L19: 1 | M19: 2 | N19: 3 | O19: =IF(H19="","",AVERAGE(J19:N19)) -> 1.8 | P19: =VLOOKUP(E19,Emission_Factors!$A:$D,4,FALSE()) -> 0.008 | Q19: =IF(AND(H19<>"",O19<>""),IF(O19<=$D$3,H19,P19),P19) -> 0.007 | R19: =IF(H19="","Secondary (no PCF)",IF(O19<=$D$3,"Supplier-specific","Secondary (DQR fail)")) -> Supplier-specific | S19: =F19*Q19 -> 567 | T19: =F19*P19 -> 648 | U19: =S19-T19 -> -81 | V19: =IF(R19="Supplier-specific","Annual PCF update via PACT",IF(R19="Secondary (DQR fail)","Improve data quality: primary energy data","Send PCF request + survey")) -> Annual PCF update via PACT
A20: S15 | B20: GlassFibre Components | C20: CZ | D20: Glass fibre | E20: EF19 | F20: 450 | G20: 900 | O20: =IF(H20="","",AVERAGE(J20:N20)) | P20: =VLOOKUP(E20,Emission_Factors!$A:$D,4,FALSE()) -> 1.6 | Q20: =IF(AND(H20<>"",O20<>""),IF(O20<=$D$3,H20,P20),P20) -> 1.6 | R20: =IF(H20="","Secondary (no PCF)",IF(O20<=$D$3,"Supplier-specific","Secondary (DQR fail)")) -> Secondary (no PCF) | S20: =F20*Q20 -> 720 | T20: =F20*P20 -> 720 | U20: =S20-T20 -> 0 | V20: =IF(R20="Supplier-specific","Annual PCF update via PACT",IF(R20="Secondary (DQR fail)","Improve data quality: primary energy data","Send PCF request + survey")) -> Send PCF request + survey
A21: S16 | B21: BuildAdd Chemicals | C21: DE | D21: Gypsum additives | E21: EF20 | F21: 225 | G21: 1100 | O21: =IF(H21="","",AVERAGE(J21:N21)) | P21: =VLOOKUP(E21,Emission_Factors!$A:$D,4,FALSE()) -> 2.3 | Q21: =IF(AND(H21<>"",O21<>""),IF(O21<=$D$3,H21,P21),P21) -> 2.3 | R21: =IF(H21="","Secondary (no PCF)",IF(O21<=$D$3,"Supplier-specific","Secondary (DQR fail)")) -> Secondary (no PCF) | S21: =F21*Q21 -> 517.5 | T21: =F21*P21 -> 517.5 | U21: =S21-T21 -> 0 | V21: =IF(R21="Supplier-specific","Annual PCF update via PACT",IF(R21="Secondary (DQR fail)","Improve data quality: primary energy data","Send PCF request + survey")) -> Send PCF request + survey
A22: TOTAL | F22: =SUM(F6:F21) -> 884570 | G22: =SUM(G6:G21) -> 96600 | O22: =IFERROR(AVERAGE(O6:O21),"") -> 2.175 | S22: =SUM(S6:S21) -> 37951 | T22: =SUM(T6:T21) -> 43448.5 | U22: =SUM(U6:U21) -> -5497.5
A24: Legend: TeR/GeR/TiR = technological/geographical/temporal representativeness; Compl. = completeness; Reliab. = reliability (PACT Pathfinder v3). Example row S01 shows the expected input format.

Sheet GHG_Inventory
A1: Corporate GHG Inventory – Scope 1, 2, 3 (t CO₂e)
A2: GHG Protocol Corporate & Scope 3 Standard · operational control · activity × EF / 1,000
A4: Code | B4: Emission source | C4: Activity | D4: Unit | E4: EF ID | F4: EF (kg/unit) | G4: t CO₂e | H4: Method | I4: DQ (1-5) | J4: Comment
A5: SCOPE 1 – Direct emissions
A6: S1 | B6: Board mills – natural gas | C6: =Company_Inputs!$B$13*PCF_Board!$C$15 -> 6.7544091e+08 | D6: kWh | E6: EF01 | F6: =VLOOKUP(E6,Emission_Factors!$A:$D,4,FALSE()) -> 0.201 | G6: =C6*F6/1000 -> 135763.62 | H6: Metered | I6: 1 | J6: Board t × kWh/t
A7: S1 | B7: Folding carton plants – natural gas | C7: =Company_Inputs!$B$8*PCF_FoldingCarton!$C$16 -> 8400000 | D7: kWh | E7: EF01 | F7: =VLOOKUP(E7,Emission_Factors!$A:$D,4,FALSE()) -> 0.201 | G7: =C7*F7/1000 -> 1688.4 | H7: Metered | I7: 1
A8: S1 | B8: Gypsum board plants – natural gas (calcination + drying) | C8: =Company_Inputs!$B$9*(PCF_GypsumBoard!$C$22+PCF_GypsumBoard!$C$23) -> 301500000 | D8: kWh | E8: EF01 | F8: =VLOOKUP(E8,Emission_Factors!$A:$D,4,FALSE()) -> 0.201 | G8: =C8*F8/1000 -> 60601.5 | H8: Metered | I8: 1
A9: S1 | B9: Mobile combustion – diesel | C9: =Company_Inputs!$B$20 -> 1500000 | D9: l | E9: EF29 | F9: =VLOOKUP(E9,Emission_Factors!$A:$D,4,FALSE()) -> 2.65 | G9: =C9*F9/1000 -> 3975 | H9: Fuel records | I9: 1
A10: SCOPE 2 – Purchased electricity
A11: S2-LB | B11: Electricity – location-based (all sites) | C11: =Company_Inputs!$B$13*PCF_Board!$C$17+Company_Inputs!$B$8*PCF_FoldingCarton!$C$18+Company_Inputs!$B$9*PCF_GypsumBoard!$C$25 -> 2.3204318e+08 | D11: kWh | E11: EF03 | F11: =VLOOKUP(E11,Emission_Factors!$A:$D,4,FALSE()) -> 0.363 | G11: =C11*F11/1000 -> 84231.675 | H11: Metered | I11: 1 | J11: Reported; not added to MB
A12: S2-MB | B12: Electricity – market-based (non-certified share × residual mix) | C12: =C11*(1-Company_Inputs!$B$21) -> 1.7403239e+08 | D12: kWh | E12: EF31 | F12: =VLOOKUP(E12,Emission_Factors!$A:$D,4,FALSE()) -> 0.62 | G12: =C12*F12/1000 -> 107900.08 | H12: Contracts | I12: 2 | J12: Green share in Company_Inputs
A13: SCOPE 3 – Value chain
A14: S3-01 | B14: Cat 1 – Recovered paper | C14: =SUMIFS(Supplier_Register!$F$6:$F$21,Supplier_Register!$D$6:$D$21,"Recovered paper") -> 442000 | D14: t | E14: Register | F14: =IFERROR(G14/C14,0) -> 0.013914027 | G14: =SUMIFS(Supplier_Register!$S$6:$S$21,Supplier_Register!$D$6:$D$21,"Recovered paper") -> 6150 | H14: Hybrid (supplier/avg) | I14: 2 | J14: Supplier_Register
A15: S3-01 | B15: Cat 1 – Native starch | C15: =SUMIFS(Supplier_Register!$F$6:$F$21,Supplier_Register!$D$6:$D$21,"Native starch") -> 17200 | D15: t | E15: Register | F15: =IFERROR(G15/C15,0) -> 0.62 | G15: =SUMIFS(Supplier_Register!$S$6:$S$21,Supplier_Register!$D$6:$D$21,"Native starch") -> 10664 | H15: Hybrid (supplier/avg) | I15: 2 | J15: Supplier_Register
A16: S3-01 | B16: Cat 1 – Calcium carbonate | C16: =SUMIFS(Supplier_Register!$F$6:$F$21,Supplier_Register!$D$6:$D$21,"Calcium carbonate") -> 11900 | D16: t | E16: Register | F16: =IFERROR(G16/C16,0) -> 0.06 | G16: =SUMIFS(Supplier_Register!$S$6:$S$21,Supplier_Register!$D$6:$D$21,"Calcium carbonate") -> 714 | H16: Hybrid (supplier/avg) | I16: 2 | J16: Supplier_Register
A17: S3-01 | B17: Cat 1 – Process chemicals | C17: =SUMIFS(Supplier_Register!$F$6:$F$21,Supplier_Register!$D$6:$D$21,"Process chemicals") -> 4000 | D17: t | E17: Register | F17: =IFERROR(G17/C17,0) -> 2 | G17: =SUMIFS(Supplier_Register!$S$6:$S$21,Supplier_Register!$D$6:$D$21,"Process chemicals") -> 8000 | H17: Hybrid (supplier/avg) | I17: 4 | J17: Supplier_Register
A18: S3-01 | B18: Cat 1 – Printing ink | C18: =SUMIFS(Supplier_Register!$F$6:$F$21,Supplier_Register!$D$6:$D$21,"Printing ink") -> 1575 | D18: t | E18: Register | F18: =IFERROR(G18/C18,0) -> 2.7 | G18: =SUMIFS(Supplier_Register!$S$6:$S$21,Supplier_Register!$D$6:$D$21,"Printing ink") -> 4252.5 | H18: Hybrid (supplier/avg) | I18: 2 | J18: Supplier_Register
A19: S3-01 | B19: Cat 1 – Varnish | C19: =SUMIFS(Supplier_Register!$F$6:$F$21,Supplier_Register!$D$6:$D$21,"Varnish") -> 840 | D19: t | E19: Register | F19: =IFERROR(G19/C19,0) -> 2.5 | G19: =SUMIFS(Supplier_Register!$S$6:$S$21,Supplier_Register!$D$6:$D$21,"Varnish") -> 2100 | H19: Hybrid (supplier/avg) | I19: 3 | J19: Supplier_Register
A20: S3-01 | B20: Cat 1 – Adhesive | C20: =SUMIFS(Supplier_Register!$F$6:$F$21,Supplier_Register!$D$6:$D$21,"Adhesive") -> 525 | D20: t | E20: Register | F20: =IFERROR(G20/C20,0) -> 1.5 | G20: =SUMIFS(Supplier_Register!$S$6:$S$21,Supplier_Register!$D$6:$D$21,"Adhesive") -> 787.5 | H20: Hybrid (supplier/avg) | I20: 3 | J20: Supplier_Register
A21: S3-01 | B21: Cat 1 – Stretch film | C21: =SUMIFS(Supplier_Register!$F$6:$F$21,Supplier_Register!$D$6:$D$21,"Stretch film") -> 855 | D21: t | E21: Register | F21: =IFERROR(G21/C21,0) -> 2.6 | G21: =SUMIFS(Supplier_Register!$S$6:$S$21,Supplier_Register!$D$6:$D$21,"Stretch film") -> 2223 | H21: Hybrid (supplier/avg) | I21: 3 | J21: Supplier_Register
A22: S3-01 | B22: Cat 1 – Natural gypsum | C22: =SUMIFS(Supplier_Register!$F$6:$F$21,Supplier_Register!$D$6:$D$21,"Natural gypsum") -> 202500 | D22: t | E22: Register | F22: =IFERROR(G22/C22,0) -> 0.005 | G22: =SUMIFS(Supplier_Register!$S$6:$S$21,Supplier_Register!$D$6:$D$21,"Natural gypsum") -> 1012.5 | H22: Hybrid (supplier/avg) | I22: 2 | J22: Supplier_Register
A23: S3-01 | B23: Cat 1 – FGD gypsum | C23: =SUMIFS(Supplier_Register!$F$6:$F$21,Supplier_Register!$D$6:$D$21,"FGD gypsum") -> 121500 | D23: t | E23: Register | F23: =IFERROR(G23/C23,0) -> 0.002 | G23: =SUMIFS(Supplier_Register!$S$6:$S$21,Supplier_Register!$D$6:$D$21,"FGD gypsum") -> 243 | H23: Hybrid (supplier/avg) | I23: 3 | J23: Supplier_Register
A24: S3-01 | B24: Cat 1 – Recycled gypsum | C24: =SUMIFS(Supplier_Register!$F$6:$F$21,Supplier_Register!$D$6:$D$21,"Recycled gypsum") -> 81000 | D24: t | E24: Register | F24: =IFERROR(G24/C24,0) -> 0.007 | G24: =SUMIFS(Supplier_Register!$S$6:$S$21,Supplier_Register!$D$6:$D$21,"Recycled gypsum") -> 567 | H24: Hybrid (supplier/avg) | I24: 2 | J24: Supplier_Register
A25: S3-01 | B25: Cat 1 – Glass fibre | C25: =SUMIFS(Supplier_Register!$F$6:$F$21,Supplier_Register!$D$6:$D$21,"Glass fibre") -> 450 | D25: t | E25: Register | F25: =IFERROR(G25/C25,0) -> 1.6 | G25: =SUMIFS(Supplier_Register!$S$6:$S$21,Supplier_Register!$D$6:$D$21,"Glass fibre") -> 720 | H25: Hybrid (supplier/avg) | I25: 3 | J25: Supplier_Register
A26: S3-01 | B26: Cat 1 – Gypsum additives | C26: =SUMIFS(Supplier_Register!$F$6:$F$21,Supplier_Register!$D$6:$D$21,"Gypsum additives") -> 225 | D26: t | E26: Register | F26: =IFERROR(G26/C26,0) -> 2.3 | G26: =SUMIFS(Supplier_Register!$S$6:$S$21,Supplier_Register!$D$6:$D$21,"Gypsum additives") -> 517.5 | H26: Hybrid (supplier/avg) | I26: 4 | J26: Supplier_Register
A27: S3-01 | B27: Cat 1 – Indirect procurement (spend-based) | C27: =Company_Inputs!$B$22 -> 60000000 | D27: EUR | E27: EF23 | F27: =VLOOKUP(E27,Emission_Factors!$A:$D,4,FALSE()) -> 0.25 | G27: =C27*F27/1000 -> 15000 | H27: Spend-based | I27: 5 | J27: Replace with supplier data over time
A28: S3-02 | B28: Cat 2 – Capital goods | C28: =Company_Inputs!$B$23 -> 35000000 | D28: EUR | E28: EF24 | F28: =VLOOKUP(E28,Emission_Factors!$A:$D,4,FALSE()) -> 0.35 | G28: =C28*F28/1000 -> 12250 | H28: Spend-based | I28: 5
A29: S3-03 | B29: Cat 3 – Natural gas upstream | C29: =GHG_Inventory!$C$6+GHG_Inventory!$C$7+GHG_Inventory!$C$8 -> 9.8534091e+08 | D29: kWh | E29: EF02 | F29: =VLOOKUP(E29,Emission_Factors!$A:$D,4,FALSE()) -> 0.03 | G29: =C29*F29/1000 -> 29560.227 | H29: Average-data | I29: 3
A30: S3-03 | B30: Cat 3 – Electricity upstream & T&D losses | C30: =GHG_Inventory!$C$11 -> 2.3204318e+08 | D30: kWh | E30: EF04 | F30: =VLOOKUP(E30,Emission_Factors!$A:$D,4,FALSE()) -> 0.045 | G30: =C30*F30/1000 -> 10441.943 | H30: Average-data | I30: 3
A31: S3-03 | B31: Cat 3 – Diesel upstream | C31: =Company_Inputs!$B$20 -> 1500000 | D31: l | E31: EF30 | F31: =VLOOKUP(E31,Emission_Factors!$A:$D,4,FALSE()) -> 0.62 | G31: =C31*F31/1000 -> 930 | H31: Average-data | I31: 3
A32: S3-04 | B32: Cat 4 – Inbound RCP transport | C32: =Company_Inputs!$B$17*PCF_Board!$C$6 -> 66389659 | D32: tkm | E32: EF06 | F32: =VLOOKUP(E32,Emission_Factors!$A:$D,4,FALSE()) -> 0.095 | G32: =C32*F32/1000 -> 6307.0176 | H32: Distance-based | I32: 3 | J32: External RCP t × km
A33: S3-04 | B33: Cat 4 – Inbound gypsum transport | C33: =Company_Inputs!$B$18*PCF_GypsumBoard!$C$9 -> 32400000 | D33: tkm | E33: EF06 | F33: =VLOOKUP(E33,Emission_Factors!$A:$D,4,FALSE()) -> 0.095 | G33: =C33*F33/1000 -> 3078 | H33: Distance-based | I33: 3
A34: S3-04 | B34: Cat 4 – Internal transfers board → plants (3rd-party hauliers) | C34: =Company_Inputs!$B$11*PCF_FoldingCarton!$C$6+Company_Inputs!$B$9*PCF_GypsumBoard!$C$21 -> 35229545 | D34: tkm | E34: EF06 | F34: =VLOOKUP(E34,Emission_Factors!$A:$D,4,FALSE()) -> 0.095 | G34: =C34*F34/1000 -> 3346.8068 | H34: Distance-based | I34: 3
A35: S3-04 | B35: Cat 4 – Outbound deliveries paid by company (FC + gypsum board) | C35: =(Company_Inputs!$B$8+Company_Inputs!$B$9*Company_Inputs!$B$10)*Company_Inputs!$B$29 -> 146250000 | D35: tkm | E35: EF06 | F35: =VLOOKUP(E35,Emission_Factors!$A:$D,4,FALSE()) -> 0.095 | G35: =C35*F35/1000 -> 13893.75 | H35: Distance-based | I35: 4 | J35: GLEC: request carrier data
A36: S3-05 | B36: Cat 5 – Water & wastewater (board mills) | C36: =Company_Inputs!$B$13*PCF_Board!$C$19 -> 3178545.5 | D36: m³ | E36: EF21 | F36: =VLOOKUP(E36,Emission_Factors!$A:$D,4,FALSE()) -> 0.3 | G36: =C36*F36/1000 -> 953.56364 | H36: Average-data | I36: 3
A37: S3-05 | B37: Cat 5 – Pulper rejects to incineration | C37: =Company_Inputs!$B$13*PCF_Board!$C$20 -> 31785455 | D37: kg | E37: EF22 | F37: =VLOOKUP(E37,Emission_Factors!$A:$D,4,FALSE()) -> 0.6 | G37: =C37*F37/1000 -> 19071.273 | H37: Average-data | I37: 3
A38: S3-06 | B38: Cat 6 – Business travel | C38: =Company_Inputs!$B$24 -> 4200000 | D38: pkm | E38: EF25 | F38: =VLOOKUP(E38,Emission_Factors!$A:$D,4,FALSE()) -> 0.15 | G38: =C38*F38/1000 -> 630 | H38: Distance-based | I38: 3
A39: S3-07 | B39: Cat 7 – Employee commuting | C39: =Company_Inputs!$B$25*2*Company_Inputs!$B$26*Company_Inputs!$B$27 -> 21168000 | D39: pkm | E39: EF26 | F39: =VLOOKUP(E39,Emission_Factors!$A:$D,4,FALSE()) -> 0.17 | G39: =C39*F39/1000 -> 3598.56 | H39: Average-data | I39: 4 | J39: FTE × 2 × km × days
A40: S3-09 | B40: Cat 9 – External board collected by customers | C40: =Company_Inputs!$B$7*Company_Inputs!$B$28 -> 52000000 | D40: tkm | E40: EF06 | F40: =VLOOKUP(E40,Emission_Factors!$A:$D,4,FALSE()) -> 0.095 | G40: =C40*F40/1000 -> 4940 | H40: Distance-based | I40: 4
A41: S3-10 | B41: Cat 10 – Processing of sold board by external converters | C41: =Company_Inputs!$B$7 -> 260000 | D41: t | E41: Proxy | F41: =(PCF_FoldingCarton!$C$18*Emission_Factors!$D$7+PCF_FoldingCarton!$C$16*Emission_Factors!$D$5)/(1000/(1-PCF_FoldingCarton!$C$5))*1000 -> 94.0104 | G41: =C41*F41/1000 -> 24442.704 | H41: Proxy: own converting | I41: 4 | J41: Own FC energy intensity per t board as proxy (kg/t)
...

Sheet Supplier_Scorecard
A1: Supplier ESG Scorecard & Risk Prioritisation
A2: Themes aligned with EcoVadis (Environment, Labour & Human Rights, Ethics, Sustainable Procurement) + Climate data maturity
A3: Weights | E3: Environment | F3: Labour & HR | G3: Ethics | H3: Sust. procurement | I3: Climate maturity
E4: 0.3 | F4: 0.2 | G4: 0.15 | H4: 0.1 | I4: 0.25 | J4: =SUM(E4:I4) -> 1 | K4: =IF(ROUND(J4,4)=1,"OK","≠100%") -> OK
A6: ID | B6: Supplier | C6: Material | D6: EcoVadis score | E6: Environ. | F6: Labour & HR | G6: Ethics | H6: Sust. proc. | I6: Climate maturity | J6: SBTi (Y/N) | K6: ISO 14001 | L6: ISO 50001 | M6: PCF accepted | N6: Total score | O6: Rating | P6: Spend (EUR k) | Q6: Emissions (t CO₂e) | R6: Risk index | S6: Recommended action
A7: =Supplier_Register!A6 -> S01 | B7: =Supplier_Register!B6 -> Recycling Partner North | C7: =Supplier_Register!D6 -> Recovered paper | D7: 68 | E7: 72 | F7: 65 | G7: 70 | H7: 55 | I7: =40*(J7="Y")+30*(M7="Y")+15*(K7="Y")+15*(L7="Y") -> 100 | J7: Y | K7: Y | L7: Y | M7: =IF(Supplier_Register!R6="Supplier-specific","Y","N") -> Y | N7: =SUMPRODUCT(E7:I7,$E$4:$I$4) -> 75.6 | O7: =IF(N7>=70,"A – Strategic partner",IF(N7>=55,"B – Develop",IF(N7>=40,"C – Improvement plan","D – Escalate"))) -> A – Strategic partner | P7: =Supplier_Register!G6 -> 19200 | Q7: =Supplier_Register!S6 -> 1920 | R7: =Q7/SUM($Q$7:$Q$22)*(100-N7) -> 1.2344339 | S7: =IF(LEFT(O7,1)="A","Joint decarb. roadmap, PCF exchange",IF(LEFT(O7,1)="B","Request EcoVadis + SBTi commitment",IF(LEFT(O7,1)="C","Corrective action plan within 6 months","Escalate to category mgmt; audit"))) -> Joint decarb. roadmap, PCF exchange
A8: =Supplier_Register!A7 -> S02 | B8: =Supplier_Register!B7 -> Recycling Partner South | C8: =Supplier_Register!D7 -> Recovered paper | E8: 50 | F8: 55 | G8: 60 | H8: 35 | I8: =40*(J8="Y")+30*(M8="Y")+15*(K8="Y")+15*(L8="Y") -> 15 | J8: N | K8: Y | L8: N | M8: =IF(Supplier_Register!R7="Supplier-specific","Y","N") -> N | N8: =SUMPRODUCT(E8:I8,$E$4:$I$4) -> 42.25 | O8: =IF(N8>=70,"A – Strategic partner",IF(N8>=55,"B – Develop",IF(N8>=40,"C – Improvement plan","D – Escalate"))) -> C – Improvement plan | P8: =Supplier_Register!G7 -> 16200 | Q8: =Supplier_Register!S7 -> 2025 | R8: =Q8/SUM($Q$7:$Q$22)*(100-N8) -> 3.0814405 | S8: =IF(LEFT(O8,1)="A","Joint decarb. roadmap, PCF exchange",IF(LEFT(O8,1)="B","Request EcoVadis + SBTi commitment",IF(LEFT(O8,1)="C","Corrective action plan within 6 months","Escalate to category mgmt; audit"))) -> Corrective action plan within 6 months
A9: =Supplier_Register!A8 -> S03 | B9: =Supplier_Register!B8 -> Municipal Paper Collection Pool | C9: =Supplier_Register!D8 -> Recovered paper | E9: 40 | F9: 50 | G9: 55 | H9: 30 | I9: =40*(J9="Y")+30*(M9="Y")+15*(K9="Y")+15*(L9="Y") -> 0 | J9: N | K9: N | L9: N | M9: =IF(Supplier_Register!R8="Supplier-specific","Y","N") -> N | N9: =SUMPRODUCT(E9:I9,$E$4:$I$4) -> 33.25 | O9: =IF(N9>=70,"A – Strategic partner",IF(N9>=55,"B – Develop",IF(N9>=40,"C – Improvement plan","D – Escalate"))) -> D – Escalate | P9: =Supplier_Register!G8 -> 10100 | Q9: =Supplier_Register!S8 -> 1380 | R9: =Q9/SUM($Q$7:$Q$22)*(100-N9) -> 2.4272088 | S9: =IF(LEFT(O9,1)="A","Joint decarb. roadmap, PCF exchange",IF(LEFT(O9,1)="B","Request EcoVadis + SBTi commitment",IF(LEFT(O9,1)="C","Corrective action plan within 6 months","Escalate to category mgmt; audit"))) -> Escalate to category mgmt; audit
A10: =Supplier_Register!A9 -> S04 | B10: =Supplier_Register!B9 -> RCP Trader Benelux | C10: =Supplier_Register!D9 -> Recovered paper | D10: 45 | E10: 45 | F10: 50 | G10: 45 | H10: 30 | I10: =40*(J10="Y")+30*(M10="Y")+15*(K10="Y")+15*(L10="Y") -> 15 | J10: N | K10: Y | L10: N | M10: =IF(Supplier_Register!R9="Supplier-specific","Y","N") -> N | N10: =SUMPRODUCT(E10:I10,$E$4:$I$4) -> 37 | O10: =IF(N10>=70,"A – Strategic partner",IF(N10>=55,"B – Develop",IF(N10>=40,"C – Improvement plan","D – Escalate"))) -> D – Escalate | P10: =Supplier_Register!G9 -> 6900 | Q10: =Supplier_Register!S9 -> 825 | R10: =Q10/SUM($Q$7:$Q$22)*(100-N10) -> 1.3695291 | S10: =IF(LEFT(O10,1)="A","Joint decarb. roadmap, PCF exchange",IF(LEFT(O10,1)="B","Request EcoVadis + SBTi commitment",IF(LEFT(O10,1)="C","Corrective action plan within 6 months","Escalate to category mgmt; audit"))) -> Escalate to category mgmt; audit
A11: =Supplier_Register!A10 -> S05 | B11: =Supplier_Register!B10 -> Starch Mill Central | C11: =Supplier_Register!D10 -> Native starch | D11: 74 | E11: 78 | F11: 70 | G11: 72 | H11: 65 | I11: =40*(J11="Y")+30*(M11="Y")+15*(K11="Y")+15*(L11="Y") -> 100 | J11: Y | K11: Y | L11: Y | M11: =IF(Supplier_Register!R10="Supplier-specific","Y","N") -> Y | N11: =SUMPRODUCT(E11:I11,$E$4:$I$4) -> 79.7 | O11: =IF(N11>=70,"A – Strategic partner",IF(N11>=55,"B – Develop",IF(N11>=40,"C – Improvement plan","D – Escalate"))) -> A – Strategic partner | P11: =Supplier_Register!G10 -> 8600 | Q11: =Supplier_Register!S10 -> 10664 | R11: =Q11/SUM($Q$7:$Q$22)*(100-N11) -> 5.7041764 | S11: =IF(LEFT(O11,1)="A","Joint decarb. roadmap, PCF exchange",IF(LEFT(O11,1)="B","Request EcoVadis + SBTi commitment",IF(LEFT(O11,1)="C","Corrective action plan within 6 months","Escalate to category mgmt; audit"))) -> Joint decarb. roadmap, PCF exchange
A12: =Supplier_Register!A11 -> S06 | B12: =Supplier_Register!B11 -> Mineral Fillers Alpine | C12: =Supplier_Register!D11 -> Calcium carbonate | D12: 61 | E12: 65 | F12: 60 | G12: 62 | H12: 50 | I12: =40*(J12="Y")+30*(M12="Y")+15*(K12="Y")+15*(L12="Y") -> 60 | J12: N | K12: Y | L12: Y | M12: =IF(Supplier_Register!R11="Supplier-specific","Y","N") -> Y | N12: =SUMPRODUCT(E12:I12,$E$4:$I$4) -> 60.8 | O12: =IF(N12>=70,"A – Strategic partner",IF(N12>=55,"B – Develop",IF(N12>=40,"C – Improvement plan","D – Escalate"))) -> B – Develop | P12: =Supplier_Register!G11 -> 1500 | Q12: =Supplier_Register!S11 -> 714 | R12: =Q12/SUM($Q$7:$Q$22)*(100-N12) -> 0.73749835 | S12: =IF(LEFT(O12,1)="A","Joint decarb. roadmap, PCF exchange",IF(LEFT(O12,1)="B","Request EcoVadis + SBTi commitment",IF(LEFT(O12,1)="C","Corrective action plan within 6 months","Escalate to category mgmt; audit"))) -> Request EcoVadis + SBTi commitment
